<?xml version="1.0" ?>
<robot name="panda" xmlns:xacro="http://www.ros.org/wiki/xacro">
  <material name="Vis"><color rgba="0.0 0.0 0.0 0.0"/></material>
  <link name="panda_link0">
    <visual>
      <geometry>
        <mesh filename="package://franka_description/meshes/visual/link0.dae"/>
      </geometry>
    </visual>
    <collision>
      <geometry>
        <mesh filename="package://franka_description/meshes/collision/link0.obj"/>
      </geometry>
    </collision>
  </link>
  <link name="panda_link1">
    <visual>
      <geometry>
        <mesh filename="package://franka_description/meshes/visual/link1.dae"/>
      </geometry>
    </visual>
    <collision>
      <geometry>
        <mesh filename="package://franka_description/meshes/collision/link1.obj"/>
      </geometry>
    </collision>
  </link>
  <joint name="panda_joint1" type="revolute">
    <safety_controller k_position="100.0" k_velocity="40.0" soft_lower_limit="-2.8973" soft_upper_limit="2.8973"/>
    <origin rpy="0 0 0" xyz="0 0 0.333"/>
    <parent link="panda_link0"/>
    <child link="panda_link1"/>
    <axis xyz="0 0 1"/>
    <dynamics damping="10.0"/>
    <limit effort="87" lower="-2.8973" upper="2.8973" velocity="2.1750"/>
  </joint>
  <link name="panda_link2">
    <visual>
      <geometry>
        <mesh filename="package://franka_description/meshes/visual/link2.dae"/>
      </geometry>
    </visual>
    <collision>
      <geometry>
        <mesh filename="package://franka_description/meshes/collision/link2.obj"/>
      </geometry>
    </collision>
  </link>
  <joint name="panda_joint2" type="revolute">
    <safety_controller k_position="100.0" k_velocity="40.0" soft_lower_limit="-1.7628" soft_upper_limit="1.7628"/>
    <origin rpy="-1.57079632679 0 0" xyz="0 0 0"/>
    <parent link="panda_link1"/>
    <child link="panda_link2"/>
    <axis xyz="0 0 1"/>
    <dynamics damping="10.0"/>
    <limit effort="87" lower="-1.7628" upper="1.7628" velocity="2.1750"/>
  </joint>
  <link name="panda_link3">
    <visual>
      <geometry>
        <mesh filename="package://franka_description/meshes/visual/link3.dae"/>
      </geometry>
    </visual>
    <collision>
      <geometry>
        <mesh filename="package://franka_description/meshes/collision/link3.obj"/>
      </geometry>
    </collision>
  </link>
  <joint name="panda_joint3" type="revolute">
    <safety_controller k_position="100.0" k_velocity="40.0" soft_lower_limit="-2.8973" soft_upper_limit="2.8973"/>
    <origin rpy="1.57079632679 0 0" xyz="0 -0.316 0"/>
    <parent link="panda_link2"/>
    <child link="panda_link3"/>
    <axis xyz="0 0 1"/>
    <dynamics damping="10.0"/>
    <limit effort="87" lower="-2.8973" upper="2.8973" velocity="2.1750"/>
  </joint>
  <link name="panda_link4">
    <visual>
      <geometry>
        <mesh filename="package://franka_description/meshes/visual/link4.dae"/>
      </geometry>
    </visual>
    <collision>
      <geometry>
        <mesh filename="package://franka_description/meshes/collision/link4.obj"/>
      </geometry>
    </collision>
  </link>
  <joint name="panda_joint4" type="revolute">
    <safety_controller k_position="100.0" k_velocity="40.0" soft_lower_limit="-3.0718" soft_upper_limit="-0.0698"/>
    <origin rpy="1.57079632679 0 0" xyz="0.0825 0 0"/>
    <parent link="panda_link3"/>
    <child link="panda_link4"/>
    <axis xyz="0 0 1"/>
    <dynamics damping="10.0"/>
    <limit effort="87" lower="-3.0718" upper="-0.0698" velocity="2.1750"/>
    <!-- something is weird with this joint limit config
    <dynamics damping="10.0"/>
    <limit effort="87" lower="-3.0" upper="0.087" velocity="2.1750"/>  -->
  </joint>
  <link name="panda_link5">
    <visual>
      <geometry>
        <mesh filename="package://franka_description/meshes/visual/link5.dae"/>
      </geometry>
    </visual>
    <collision>
      <geometry>
        <mesh filename="package://franka_description/meshes/collision/link5.obj"/>
      </geometry>
    </collision>
  </link>
  <joint name="panda_joint5" type="revolute">
    <safety_controller k_position="100.0" k_velocity="40.0" soft_lower_limit="-2.8973" soft_upper_limit="2.8973"/>
    <origin rpy="-1.57079632679 0 0" xyz="-0.0825 0.384 0"/>
    <parent link="panda_link4"/>
    <child link="panda_link5"/>
    <axis xyz="0 0 1"/>
    <dynamics damping="10.0"/>
    <limit effort="12" lower="-2.8973" upper="2.8973" velocity="2.6100"/>
  </joint>
  <link name="panda_link6">
    <visual>
      <geometry>
        <mesh filename="package://franka_description/meshes/visual/link6.dae"/>
      </geometry>
    </visual>
    <collision>
      <geometry>
        <mesh filename="package://franka_description/meshes/collision/link6.obj"/>
      </geometry>
    </collision>
  </link>
  <joint name="panda_joint6" type="revolute">
    <safety_controller k_position="100.0" k_velocity="40.0" soft_lower_limit="-0.0175" soft_upper_limit="3.7525"/>
    <origin rpy="1.57079632679 0 0" xyz="0 0 0"/>
    <parent link="panda_link5"/>
    <child link="panda_link6"/>
    <axis xyz="0 0 1"/>
    <dynamics damping="10.0"/>
    <limit effort="12" lower="-0.0175" upper="3.7525" velocity="2.6100"/>
    <!-- <dynamics damping="10.0"/>
    <limit effort="12" lower="-0.0873" upper="3.0" velocity="2.6100"/> -->
  </joint>
  <link name="panda_link7">
    <visual>
      <geometry>
        <mesh filename="package://franka_description/meshes/visual/link7.dae"/>
      </geometry>
    </visual>
    <collision>
      <geometry>
        <mesh filename="package://franka_description/meshes/collision/link7.obj"/>
      </geometry>
    </collision>
  </link>
  <joint name="panda_joint7" type="revolute">
    <safety_controller k_position="100.0" k_velocity="40.0" soft_lower_limit="-2.8973" soft_upper_limit="2.8973"/>
    <origin rpy="1.57079632679 0 0" xyz="0.088 0 0"/>
    <parent link="panda_link6"/>
    <child link="panda_link7"/>
    <axis xyz="0 0 1"/>
    <dynamics damping="10.0"/>
    <limit effort="12" lower="-2.8973" upper="2.8973" velocity="2.6100"/>
  </joint>
  <!--
  <link name="panda_link8"/>
  <joint name="panda_joint8" type="fixed">
    <origin rpy="0 0 0" xyz="0 0 0.107"/>
    <parent link="panda_link7"/>
    <child link="panda_link8"/>
    <axis xyz="0 0 0"/>
  </joint>
  Removing this joint seems to help with some stability things
  -->
  <joint name="panda_hand_joint" type="fixed">
    <!--
    <parent link="panda_link8"/>
    -->
    <parent link="panda_link7"/>
    <child link="panda_hand"/>
    <origin rpy="0 0 -0.785398163397" xyz="0 0 0.107"/>
    <!--
    <origin rpy="0 0 -0.785398163397" xyz="0 0 0"/>
    -->
  </joint>
  <link name="panda_hand">
    <visual>
      <geometry>
        <mesh filename="package://franka_description/meshes/visual/hand.dae"/>
      </geometry>
    </visual>
    <collision>
      <geometry>
        <mesh filename="package://franka_description/meshes/collision/hand.obj"/>
      </geometry>
    </collision>
  </link>
  <joint name="panda_hand_y_axis_joint" type="fixed">
    <parent link="panda_hand"/>
    <child link="panda_hand_y_axis"/>
    <origin rpy="0 0 0" xyz="0 0.01 0"/>
  </joint>
  <link name="panda_hand_y_axis">
  </link>
  <joint name="panda_hand_z_axis_joint" type="fixed">
    <parent link="panda_hand"/>
    <child link="panda_hand_z_axis"/>
    <origin rpy="0 0 0" xyz="0 0 0.01"/>
  </joint>
  <link name="panda_hand_z_axis">
  </link>

  <link name="panda_leftfinger">
  	<inertial>
      <origin rpy="0 0 0" xyz="0 0 0"/>
      <mass value="0.0140552232"/>
      <inertia ixx="4.20413082650939E-06" ixy="0.0" ixz="0.0" iyy="3.90263687466755E-06" iyz="0" izz="1.33474964199095E-06"/>
    </inertial>
    <visual>
      <origin rpy="1.57 0 3.14" xyz="0 0 0.01"/>
      <geometry>
        <mesh filename="package://franka_description_digit/meshes/visual/digit_attachment.obj"/>
      </geometry>
    </visual>
    <collision>
      <!-- <origin rpy="1.57 0 3.14" xyz="0 1.57 0 3.140 0.01"/>
      <geometry>
        <mesh filename="package://franka_description_digit/meshes/collision/digit_attachment.obj"/>
      </geometry> -->
      <origin rpy="0 0 0" xyz="0 0 -0.03"/>
      <geometry>
        <mesh filename="package://franka_description_digit/meshes/collision/finger.obj"/>
      </geometry>
    </collision>
    <!-- <sdf resolution="256"/> -->
  </link>

  <link name="panda_rightfinger">    
  	<inertial>
      <origin rpy="1.57 0 0" xyz="0 0 0"/>
      <mass value="0.0140552232"/>
      <inertia ixx="4.20413082650939E-06" ixy="0.0" ixz="0.0" iyy="3.90263687466755E-06" iyz="0" izz="1.33474964199095E-06"/>
    </inertial>
    <visual>
      <origin rpy="1.57 0 0" xyz="0 0 0.01"/>
      <geometry>
        <mesh filename="package://franka_description_digit/meshes/visual/digit_attachment.obj"/>
      </geometry>
    </visual>
    <collision>
      <!-- <origin rpy="1.57 0 0" xyz="0 0 0.01"/>
      <geometry>
        <mesh filename="package://franka_description_digit/meshes/collision/digit_attachment.obj"/>
      </geometry> -->
      <origin rpy="0 0 3.14159265359" xyz="0 0 -0.03"/>
      <geometry>
        <mesh filename="package://franka_description_digit/meshes/collision/finger.obj"/>
      </geometry>
    </collision>
    <!-- <sdf resolution="256"/> -->
  </link>

  <joint name="panda_finger_joint1" type="prismatic">
    <parent link="panda_hand"/>
    <child link="panda_leftfinger"/>
    <origin rpy="0 0 0" xyz="0 0.03 0.095"/>
    <!-- <origin rpy="3.14 0 0" xyz="0 0 0.095"/> -->
    <axis xyz="0 1 0"/>
    <dynamics damping="10.0"/>
    <limit effort="20" lower="0.00" upper="0.04" velocity="0.2"/>
  </joint>

  <joint name="panda_finger_joint2" type="prismatic">
    <parent link="panda_hand"/>
    <child link="panda_rightfinger"/>
    <origin rpy="0 0 0" xyz="0 -0.03 0.095"/>
    <axis xyz="0 -1 0"/>
    <dynamics damping="10.0"/>
    <limit effort="20" lower="0.00" upper="0.04" velocity="0.2"/>
    <mimic joint="panda_finger_joint1"/>
  </joint>

  <joint name="panda_grip_vis_joint" type="fixed">
    <parent link="panda_hand"/>
    <child link="panda_grip_site"/>
    <origin rpy="0 0 0" xyz="0 0 0.1025"/>
  </joint>
  <link name="panda_grip_site">
    <visual>
      <geometry>
        <sphere radius="0.005"/>
      </geometry>
      <material name="Vis"/>
    </visual>
  </link>

  <joint name="panda_leftfinger_tip_joint" type="fixed">
     <!-- <origin xyz="0.0 0.0441 0.0058" rpy="-1.57 0 -1.57" /> -->
     <origin xyz="0.0 -0.0075 0.0058" rpy="-1.57 0 -1.57" />
     <parent link="panda_leftfinger"/>
     <child link="panda_leftfinger_tip" />
     <!-- <dynamics friction="100" damping="100" /> -->
     <axis xyz="0 1 0"/>
     <limit effort="100" velocity="100"/>
  </joint>

  <link name="panda_leftfinger_tip">
    <contact>
        <friction_anchor/>
        <lateral_friction value="1"/>
        <rolling_friction value="0.1"/>
        <contact_cfm value="0.0"/>
        <contact_erp value="1.0"/>
      </contact>
      <inertial>
        <origin rpy="0 0 0" xyz="0 0 0"/>
        <mass value="0.0140552232"/>
        <inertia ixx="4.20413082650939E-06" ixy="0.0" ixz="0.0" iyy="3.90263687466755E-06" iyz="0" izz="1.33474964199095E-06"/>
      </inertial>
      <visual>
          <geometry>
             <mesh filename="package://franka_description_digit/digit_center/digit_center_cam.stl"/>
          </geometry>
          <material name="red">
            <color rgba="1. 0. 0. 1"/>
          </material>
      </visual>
      <collision>
          <geometry>
            <box size="0.013 0.004 0.013"/>
            <!-- <box size="0.03 0.03 0.03"/> -->
          </geometry>
          <!-- <geometry>
             <mesh filename="package://franka_description_digit/digit_center/digit_center_cam.stl"/>
         </geometry>
         <sdf resolution="512"/> -->
     </collision>
  </link>

  <joint name="panda_rightfinger_tip_joint" type="fixed">
     <origin xyz="0.0 0.008 0.0058" rpy="-1.57 0 1.57" />
      <!-- <origin xyz="0.0 0.008 -0.0" rpy="0 3.14 -1.57" /> -->
     <!-- <origin xyz="-0.06 0.045 0.0" rpy="-3.14 -0.12 -3.14" /> -->
     <parent link="panda_rightfinger"/>
     <child link="panda_rightfinger_tip" />
     <dynamics friction="100" damping="100" />
     <axis xyz="0 -1 0"/>
     <limit effort="100" velocity="100"/>
  </joint>

  <link name="panda_rightfinger_tip">
    <contact>
        <friction_anchor/>
        <lateral_friction value="1"/>
        <rolling_friction value="0.1"/>
        <contact_cfm value="0.0"/>
        <contact_erp value="1.0"/>
      </contact>
      <inertial>
        <origin rpy="0 0 0" xyz="0 0 0"/>
        <mass value="0.0140552232"/>
        <inertia ixx="4.20413082650939E-06" ixy="0.0" ixz="0.0" iyy="3.90263687466755E-06" iyz="0" izz="1.33474964199095E-06"/>
      </inertial>
      <visual>
          <geometry>
             <mesh filename="package://franka_description_digit/digit_center/digit_center_cam.stl"/>
          </geometry>
          <material name="green">
            <color rgba="0. 1. 0. 1"/>
          </material>
      </visual>
      <collision>
          <geometry>
            <box size="0.013 0.004 0.013"/>
            <!-- <box size="0.03 0.03 0.03"/> -->
          </geometry>
          <!-- <geometry>
             <mesh filename="package://franka_description_digit/digit_center/digit_center_cam.stl"/>
         </geometry>
         <sdf resolution="512"/> -->
     </collision>
  </link>

</robot>


