<?xml version="1.0" ?>
<!-- =================================================================================== -->
<!-- |    This document was autogenerated by xacro from panda_arm_hand.urdf.xacro      | -->
<!-- |    EDITING THIS FILE BY HAND IS NOT RECOMMENDED                                 | -->
<!-- =================================================================================== -->
<robot name="panda" xmlns:xacro="http://www.ros.org/wiki/xacro">
  <link name="panda_link0">
    <visual>
      <geometry>
        <mesh filename="package://franka_description_digit/meshes/visual/link0.dae"/>
      </geometry>
    </visual>
    <collision>
      <geometry>
        <mesh filename="package://franka_description_digit/meshes/collision/link0.stl"/>
      </geometry>
    </collision>
    <inertial>
      <origin rpy="0 0 0" xyz="0 0 0"/>
      <mass value="2.8142028896"/>
      <inertia ixx="0.0129886979" ixy="0.0" ixz="0.0" iyy="0.0165355284" iyz="0" izz="0.0203311636"/>
    </inertial>
  </link>
  <link name="panda_link1">
    <visual>
      <geometry>
        <mesh filename="package://franka_description_digit/meshes/visual/link1.dae"/>
      </geometry>
    </visual>
    <collision>
      <geometry>
        <mesh filename="package://franka_description_digit/meshes/collision/link1.stl"/>
      </geometry>
    </collision>
    <inertial>
      <origin rpy="0 0 0" xyz="0 0 0"/>
      <mass value="2.3599995791"/>
      <inertia ixx="0.0186863903" ixy="0.0" ixz="0.0" iyy="0.0143789874" iyz="0" izz="0.00906812"/>
    </inertial>
  </link>
  <joint name="panda_joint1" type="revolute">
    <safety_controller k_position="100.0" k_velocity="40.0" soft_lower_limit="-2.8973" soft_upper_limit="2.8973"/>
    <origin rpy="0 0 0" xyz="0 0 0.333"/>
    <parent link="panda_link0"/>
    <child link="panda_link1"/>
    <axis xyz="0 0 1"/>
    <limit effort="87" lower="-2.8973" upper="2.8973" velocity="2.1750"/>
  </joint>
  <link name="panda_link2">
    <visual>
      <geometry>
        <mesh filename="package://franka_description_digit/meshes/visual/link2.dae"/>
      </geometry>
    </visual>
    <collision>
      <geometry>
        <mesh filename="package://franka_description_digit/meshes/collision/link2.stl"/>
      </geometry>
    </collision>
    <inertial>
      <origin rpy="0 0 0" xyz="0 0 0"/>
      <mass value="2.379518833"/>
      <inertia ixx="0.0190388734" ixy="0.0" ixz="0.0" iyy="0.0091429124" iyz="0" izz="0.014697537"/>
    </inertial>
  </link>
  <joint name="panda_joint2" type="revolute">
    <safety_controller k_position="100.0" k_velocity="40.0" soft_lower_limit="-1.7628" soft_upper_limit="1.7628"/>
    <origin rpy="-1.57079632679 0 0" xyz="0 0 0"/>
    <parent link="panda_link1"/>
    <child link="panda_link2"/>
    <axis xyz="0 0 1"/>
    <limit effort="87" lower="-1.7628" upper="1.7628" velocity="2.1750"/>
  </joint>
  <link name="panda_link3">
    <visual>
      <geometry>
        <mesh filename="package://franka_description_digit/meshes/visual/link3.dae"/>
      </geometry>
    </visual>
    <collision>
      <geometry>
        <mesh filename="package://franka_description_digit/meshes/collision/link3.stl"/>
      </geometry>
    </collision>
    <inertial>
      <origin rpy="0 0 0" xyz="0 0 0"/>
      <mass value="2.6498823337"/>
      <inertia ixx="0.0129300178" ixy="0.0" ixz="0.0" iyy="0.0150242121" iyz="0" izz="0.0142734598"/>
    </inertial>
  </link>
  <joint name="panda_joint3" type="revolute">
    <safety_controller k_position="100.0" k_velocity="40.0" soft_lower_limit="-2.8973" soft_upper_limit="2.8973"/>
    <origin rpy="1.57079632679 0 0" xyz="0 -0.316 0"/>
    <parent link="panda_link2"/>
    <child link="panda_link3"/>
    <axis xyz="0 0 1"/>
    <limit effort="87" lower="-2.8973" upper="2.8973" velocity="2.1750"/>
  </joint>
  <link name="panda_link4">
    <visual>
      <geometry>
        <mesh filename="package://franka_description_digit/meshes/visual/link4.dae"/>
      </geometry>
    </visual>
    <collision>
      <geometry>
        <mesh filename="package://franka_description_digit/meshes/collision/link4.stl"/>
      </geometry>
    </collision>
    <inertial>
      <origin rpy="0 0 0" xyz="0 0 0"/>
      <mass value="2.6948018744"/>
      <inertia ixx="0.0133874611" ixy="0.0" ixz="0.0" iyy="0.014514325" iyz="0" izz="0.0155175551"/>
    </inertial>
  </link>
  <joint name="panda_joint4" type="revolute">
    <safety_controller k_position="100.0" k_velocity="40.0" soft_lower_limit="-3.0718" soft_upper_limit="-0.0698"/>
    <origin rpy="1.57079632679 0 0" xyz="0.0825 0 0"/>
    <parent link="panda_link3"/>
    <child link="panda_link4"/>
    <axis xyz="0 0 1"/>
    <limit effort="87" lower="-3.0718" upper="-0.0698" velocity="2.1750"/>
  </joint>
  <link name="panda_link5">
    <visual>
      <geometry>
        <mesh filename="package://franka_description_digit/meshes/visual/link5.dae"/>
      </geometry>
    </visual>
    <collision>
      <geometry>
        <mesh filename="package://franka_description_digit/meshes/collision/link5.stl"/>
      </geometry>
    </collision>
    <inertial>
      <origin rpy="0 0 0" xyz="0 0 0"/>
      <mass value="2.9812816864"/>
      <inertia ixx="0.0325565705" ixy="0.0" ixz="0.0" iyy="0.0270660472" iyz="0" izz="0.0115023375"/>
    </inertial>
  </link>
  <joint name="panda_joint5" type="revolute">
    <safety_controller k_position="100.0" k_velocity="40.0" soft_lower_limit="-2.8973" soft_upper_limit="2.8973"/>
    <origin rpy="-1.57079632679 0 0" xyz="-0.0825 0.384 0"/>
    <parent link="panda_link4"/>
    <child link="panda_link5"/>
    <axis xyz="0 0 1"/>
    <limit effort="12" lower="-2.8973" upper="2.8973" velocity="2.6100"/>
  </joint>
  <link name="panda_link6">
    <visual>
      <geometry>
        <mesh filename="package://franka_description_digit/meshes/visual/link6.dae"/>
      </geometry>
    </visual>
    <collision>
      <geometry>
        <mesh filename="package://franka_description_digit/meshes/collision/link6.stl"/>
      </geometry>
    </collision>
    <inertial>
      <origin rpy="0 0 0" xyz="0 0 0"/>
      <mass value="1.1285806309"/>
      <inertia ixx="0.0026052565" ixy="0.0" ixz="0.0" iyy="0.0039897229" iyz="0" izz="0.0047048591"/>
    </inertial>
  </link>
  <joint name="panda_joint6" type="revolute">
    <safety_controller k_position="100.0" k_velocity="40.0" soft_lower_limit="-0.0175" soft_upper_limit="3.7525"/>
    <origin rpy="1.57079632679 0 0" xyz="0 0 0"/>
    <parent link="panda_link5"/>
    <child link="panda_link6"/>
    <axis xyz="0 0 1"/>
    <limit effort="12" lower="-0.0175" upper="3.7525" velocity="2.6100"/>
  </joint>
  <link name="panda_link7">
    <visual>
      <geometry>
        <mesh filename="package://franka_description_digit/meshes/visual/link7.dae"/>
      </geometry>
    </visual>
    <collision>
      <geometry>
        <mesh filename="package://franka_description_digit/meshes/collision/link7.stl"/>
      </geometry>
    </collision>
    <inertial>
      <origin rpy="0 0 0" xyz="0 0 0"/>
      <mass value="0.4052912465"/>
      <inertia ixx="0.0006316592" ixy="0.0" ixz="0.0" iyy="0.0006319639" iyz="0" izz="0.0010607721"/>
    </inertial>
  </link>
  <joint name="panda_joint7" type="revolute">
    <safety_controller k_position="100.0" k_velocity="40.0" soft_lower_limit="-2.8973" soft_upper_limit="2.8973"/>
    <origin rpy="1.57079632679 0 0" xyz="0.088 0 0"/>
    <parent link="panda_link6"/>
    <child link="panda_link7"/>
    <axis xyz="0 0 1"/>
    <limit effort="12" lower="-2.8973" upper="2.8973" velocity="2.6100"/>
  </joint>
  <!-- <link name="panda_link8"/>
  <joint name="panda_joint8" type="fixed">
    <origin rpy="0 0 0" xyz="0 0 0.107"/>
    <parent link="panda_link7"/>
    <child link="panda_link8"/>
    <axis xyz="0 0 0"/>
  </joint> -->
  <joint name="panda_hand_joint" type="fixed">
    <!-- <parent link="panda_link8"/> -->
    <parent link="panda_link7"/>
    <child link="panda_hand"/>
    <origin rpy="0 0 -0.785398163397" xyz="0 0 0"/>
  </joint>
  <link name="panda_hand">
    <visual>
      <geometry>
        <mesh filename="package://franka_description_digit/meshes/visual/hand.dae"/>
      </geometry>
    </visual>
    <collision>
      <geometry>
        <mesh filename="package://franka_description_digit/meshes/collision/hand.stl"/>
      </geometry>
    </collision>
    <inertial>
      <origin rpy="0 0 0" xyz="0 0 0"/>
      <mass value="0.5583304799"/>
      <inertia ixx="0.0023394448" ixy="0.0" ixz="0.0" iyy="0.0005782786" iyz="0" izz="0.0021310296"/>
    </inertial>
  </link>


  <!-- <link name="panda_leftfinger">
    <visual>
      <geometry>
        <mesh filename="package://franka_description_digit/meshes/visual/finger.dae"/>
      </geometry>
    </visual>
    <collision>
      <geometry>
        <mesh filename="package://franka_description_digit/meshes/collision/finger.stl"/>
      </geometry>
    </collision>
    <inertial>
      <origin rpy="0 0 0" xyz="0 0 0"/>
      <mass value="0.0140552232"/>
      <inertia ixx="4.20413082650939E-06" ixy="0.0" ixz="0.0" iyy="3.90263687466755E-06" iyz="0" izz="1.33474964199095E-06"/>
    </inertial>
  </link> -->

  <link name="panda_leftfinger">
  	<inertial>
      <origin rpy="0 0 0" xyz="0 0 0"/>
      <mass value="0.0140552232"/>
      <inertia ixx="4.20413082650939E-06" ixy="0.0" ixz="0.0" iyy="3.90263687466755E-06" iyz="0" izz="1.33474964199095E-06"/>
    </inertial>
    <visual>
      <geometry>
        <mesh filename="package://franka_description_digit/meshes/visual/digit_attachment.obj"/>
      </geometry>
    </visual>
    <collision>
      <geometry>
        <mesh filename="package://franka_description_digit/meshes/collision/digit_attachment.obj"/>
      </geometry>
    </collision>
  </link>



  <!-- <link name="panda_rightfinger">
    <visual>
      <origin rpy="0 0 3.14159265359" xyz="0 0 0"/>
      <geometry>
        <mesh filename="package://franka_description_digit/meshes/visual/finger.dae"/>
      </geometry>
    </visual>
    <collision>
      <origin rpy="0 0 3.14159265359" xyz="0 0 0"/>
      <geometry>
        <mesh filename="package://franka_description_digit/meshes/collision/finger.stl"/>
      </geometry>
    </collision>
    <inertial>
      <origin rpy="0 0 0" xyz="0 0 0"/>
      <mass value="0.0140552232"/>
      <inertia ixx="4.20413082650939E-06" ixy="0.0" ixz="0.0" iyy="3.90263687466755E-06" iyz="0" izz="1.33474964199095E-06"/>
    </inertial>
  </link> -->

  <link name="panda_rightfinger">    
  	<inertial>
      <origin rpy="0 0 0" xyz="0 0 0"/>
      <mass value="0.0140552232"/>
      <inertia ixx="4.20413082650939E-06" ixy="0.0" ixz="0.0" iyy="3.90263687466755E-06" iyz="0" izz="1.33474964199095E-06"/>
    </inertial>
    <visual>
      <origin rpy="0 0 3.14159265359" xyz="0 0 0"/>
      <geometry>
        <mesh filename="package://franka_description_digit/meshes/visual/digit_attachment.obj"/>
      </geometry>
    </visual>
    <collision>
      <origin rpy="0 0 3.14159265359" xyz="0 0 0"/>
      <geometry>
        <mesh filename="package://franka_description_digit/meshes/collision/digit_attachment.obj"/>
      </geometry>
    </collision>
  </link>


  <joint name="panda_finger_joint1" type="prismatic">
    <parent link="panda_hand"/>
    <child link="panda_leftfinger"/>
    <!-- <origin rpy="0 0 0" xyz="0 0 -0.0584"/> -->
    <!-- <axis xyz="0 1 0"/> -->
    <origin rpy="3.14 0 0" xyz="0 0 0.095"/>
    <axis xyz="0 1 0"/>
    <limit effort="20" lower="0.020" upper="0.06" velocity="0.2"/>
  </joint>

  <joint name="panda_finger_joint2" type="prismatic">
    <parent link="panda_hand"/>
    <child link="panda_rightfinger"/>
    <!-- <origin rpy="0 0 0" xyz="0 0 0.0584"/>
    <axis xyz="0 -1 0"/> -->
    <origin rpy="3.14 0 0" xyz="0 0 0.095"/>
    <axis xyz="0 -1 0"/>
    <limit effort="20" lower="0.020" upper="0.06" velocity="0.2"/>
    <mimic joint="panda_finger_joint1"/>
  </joint>


  <link name="finger_left_tip">
      <contact>
        <friction_anchor/>
        <lateral_friction value="1"/>
        <rolling_friction value="0.1"/>
        <contact_cfm value="0.0"/>
        <contact_erp value="1.0"/>
      </contact>
      <inertial>
        <origin rpy="0 0 0" xyz="0 0 0"/>
        <mass value="0.0140552232"/>
        <inertia ixx="4.20413082650939E-06" ixy="0.0" ixz="0.0" iyy="3.90263687466755E-06" iyz="0" izz="1.33474964199095E-06"/>
      </inertial>
      <visual>
          <geometry>
             <mesh filename="package://franka_description_digit/digit_center/digit_center_cam.stl"/>
          </geometry>
          <material name="red">
            <color rgba="1. 0. 0. 1"/>
          </material>
      </visual>
      <collision>
          <geometry>
             <mesh filename="package://franka_description_digit/digit_center/digit_center_cam.stl"/>
         </geometry>
     </collision>
  </link>

  <link name="finger_right_tip">
      <contact>
        <friction_anchor/>
        <lateral_friction value="1"/>
        <rolling_friction value="0.1"/>
        <contact_cfm value="0.0"/>
        <contact_erp value="1.0"/>
      </contact>
      <inertial>
        <origin rpy="0 0 0" xyz="0 0 0"/>
        <mass value="0.0140552232"/>
        <inertia ixx="4.20413082650939E-06" ixy="0.0" ixz="0.0" iyy="3.90263687466755E-06" iyz="0" izz="1.33474964199095E-06"/>
      </inertial>
      <visual>
          <geometry>
             <mesh filename="package://franka_description_digit/digit_center/digit_center_cam.stl"/>
          </geometry>
          <material name="green">
            <color rgba="0. 1. 0. 1"/>
          </material>
      </visual>
      <collision>
          <geometry>
             <mesh filename="package://franka_description_digit/digit_center/digit_center_cam.stl"/>
         </geometry>
     </collision>
  </link>

  <joint name="joint_finger_tip_left" type="fixed">
      <origin xyz="0.0 -0.0075 0.0058" rpy="0 3.26 1.57" />
      <!-- <origin xyz="0.0 -0.008 -0.0" rpy="0 3.14 1.57" /> -->
     <parent link="panda_leftfinger"/>
     <child link="finger_left_tip" />
     <dynamics friction="100" damping="100" />
     <axis xyz="0 1 0"/>
     <limit effort="100" velocity="100"/>
  </joint>

  <joint name="joint_finger_tip_right" type="fixed">
      <origin xyz="0.0 0.008 0.0058" rpy="0 3.26 -1.57" />
      <!-- <origin xyz="0.0 0.008 -0.0" rpy="0 3.14 -1.57" /> -->
     <!-- <origin xyz="-0.06 0.045 0.0" rpy="-3.14 -0.12 -3.14" /> -->
     <parent link="panda_rightfinger"/>
     <child link="finger_right_tip" />
     <dynamics friction="100" damping="100" />
     <axis xyz="0 -1 0"/>
     <limit effort="100" velocity="100"/>
  </joint>



</robot>
